Workbook
Name мфо: [1]база!$A:$F
Name продукты: [2]Справочник!$C$3:$C$21

Sheet Xulosa
K1: OOO NARPAY INVIST
C2: =+IF(L2=[3]Справочник!Q33,1,IF(L2=[3]Справочник!Q34,2,IF(L2=[3]Справочник!Q35,3,IF(L2=[3]Справочник!Q36,4)))) -> 1 | D2: 1 | F2: =+IF(R2=[3]Справочник!J14,1) -> FALSE | J2: 1 | K2: =+IF([3]Анкета!B55=4,"Валюта запрашиваемого гарантии",IF([3]Анкета!B55=5,"Валюта запрашиваемого факторинга","Валюта запрашиваемого кредита")) -> Валюта запрашиваемого кредита | L2: UZS
J3: 2 | K3: Стоимость проекта | L3: =L4+L5 -> 9200000000
J4: 3 | K4: Сумма кредита | L4: 4900000000
J5: 4 | K5: Собственные средства | L5: 4300000000
J6: 5 | K6: =+IF([3]Анкета!B51=4,"Срок гарантии (месяцев)",IF([3]Анкета!B51=5,"Срок, дней","Срок кредита (месяцев)")) -> Срок кредита (месяцев) | L6: 84
J7: 6 | K7: Льготный период по осн. долгу (месяцев) | L7: 24
J8: 7 | K8: =+IF([3]Анкета!B56=4,"Комиссионная сумма",IF([3]Анкета!B51=5,"Дисконт ставка","Процентная ставка:")) -> Процентная ставка: | L8: 0.14
J9: Альтман модели
K11: Наименавание коэфиициента | L11: Вес коэффициента | M11: Способ расчета | N11: Результат коэффициента | O11: Финальный результат
K12: Debt Service Coverage Ratio – Қарзга хизмат кўрсатиш коэффициенти Корхонанинг Операцион фойдаси | L12: 0.05 | M12: Ф2 240 / (Ф1 570 + Ф1 730 + Ф2 180) | N12: ='1.Moliyaviy natijalar'!H3 -> 181354 | O12: =N12*L12 -> 9067.7 | Q12: Синф | R12: Тавсифи | T12: Баллар
K13: Debt/EBITDA – Умумий қарзининг корхона EBITDA даромади | L13: 0.3 | M13: Ф2 240 / (Ф1 770 + Ф1 021) | N13: ='1.Moliyaviy natijalar'!H4 -> 0.089779208 | O13: =N13*L13 -> 0.026933762 | Q13: 5 | R13: Мутлоқ тўловга лаёқатли | T13: 20 баллга тенг ва юқори
K14: Liquidity ratio – Жорий ликвидлик коэффициенти. | L14: 0.3 | M14: Ф1 390 / Ф1 600 | N14: ='1.Moliyaviy natijalar'!H5 -> 1934714.4 | O14: =N14*L14 -> 580414.31 | Q14: 4 | R14: Меъёр даражасида тўловга лаёқатли | T14: 15 баллга тенг ва юқори
K15: Leverage – Молиявий мустақиллик коэффициенти. | L15: 0.3 | M15: Ф1 480 / Ф1 400 | N15: ='1.Moliyaviy natijalar'!H6 -> 0.71500638 | O15: =N15*L15 -> 0.21450191 | Q15: 3 | R15: Паст даражада тўловга лаёқатли | T15: 10 баллга тенг ва юқори
K16: Sufficiency of WC – Соф айланма активлар билан таъминганлик коэффициенти | L16: 0.05 | M16: Ф1 390 /Ф1 400 | N16: ='1.Moliyaviy natijalar'!H7 -> 0.27296102 | O16: =N16*L16 -> 0.013648051 | Q16: 2 | R16: Молиявий барқарор бўлмаган | T16: 5 баллга тенг ва юқори
O17: =SUM(O12:O16) -> 589482.27 | Q17: 1 | R17: Риск юқори | T17: 5 баллдан паст
K18: Z=0,717x_1+ 0,847x_2+3,107x_3+0,420x_4+0,998x_5
K20: x_1 = Оборот капитали / Жами активлар | L20: Ф1 390 / Ф1 400 | M20: ='1.Moliyaviy natijalar'!G12 -> 0.27296102 | Q20: Балл
K21: x_2 = Тақсимланмаган фойда / Жами активлар | L21: Ф1 450 / Ф1 400 | M21: ='1.Moliyaviy natijalar'!G13 -> 0.0020759923 | Q21: 1 | R21: Банкротликка учраши эҳтимоллиги юқори бўлган корхона. | U21: Z < 1.23
K22: x_3 = Операцион фойда (Солиқ ва фоиз тўлагунга қадар фойда) / Жами активлар | L22: Ф2 240 / Ф1 400 | M22: ='1.Moliyaviy natijalar'!G14 -> 0.025586501 | Q22: 3 | R22: Банкротлик ҳолати ноаниқ бўлган корхона, (башорат қилиб бўлмайди). | U22: 1.23 < Z < 2.89
K23: x_4 = Ўз маблағларини баланс қиймати / Жами мажбуриятлар | L23: Ф1 480 / Ф1 770 | M23: ='1.Moliyaviy natijalar'!G15 -> 2.5088505 | Q23: 5 | R23: Банкротликка учраш эҳтимоллиги паст ва молиявий барқарор корхона. | U23: Z > 2.9
K24: x_5 = Соф тушум / Жами активлар | L24: Ф2 010 / Ф1 400 | M24: ='1.Moliyaviy natijalar'!G16 -> 0.015251391
M25: =0.717*M20+0.847*M21+3.107*M22+0.42*M23+0.998*M24 -> 1.3459068
J28: NPV/IRR
K29: Период | L29: Поток наличности | M29: Ставка Дисконта | N29: NPV | O29: IRR
L30: ='2.NPV-IRR'!I4 -> -9200000000
K31: =+'2.NPV-IRR (2)'!H5 -> 0 | L31: =+'2.NPV-IRR (2)'!I5 -> 2377093102 | M31: =+'2.NPV-IRR (2)'!J5 -> 0.17009191 | N31: =+'2.NPV-IRR (2)'!K5 -> -7.1684561e+09 | O31: =+'2.NPV-IRR (2)'!L5 -> Loyiha rad etilsin
K32: =+'2.NPV-IRR (2)'!H6 -> 0 | L32: =+'2.NPV-IRR (2)'!I6 -> 1805615699 | M32: =+'2.NPV-IRR (2)'!J6 -> 0.17009191 | N32: =+'2.NPV-IRR (2)'!K6 -> -5.8496366e+09 | O32: =+'2.NPV-IRR (2)'!L6 -> Loyiha rad etilsin
K33: =+'2.NPV-IRR (2)'!H7 -> 0 | L33: =+'2.NPV-IRR (2)'!I7 -> 2451935561 | M33: =+'2.NPV-IRR (2)'!J7 -> 0.17009191 | N33: =+'2.NPV-IRR (2)'!K7 -> -4.3190809e+09 | O33: =+'2.NPV-IRR (2)'!L7 -> Loyiha rad etilsin
K34: =+'2.NPV-IRR (2)'!H8 -> 0 | L34: =+'2.NPV-IRR (2)'!I8 -> 2678947117 | M34: =+'2.NPV-IRR (2)'!J8 -> 0.17009191 | N34: =+'2.NPV-IRR (2)'!K8 -> -2.8899098e+09 | O34: =+'2.NPV-IRR (2)'!L8 -> Loyiha rad etilsin
K35: =+'2.NPV-IRR (2)'!H9 -> 0 | L35: =+'2.NPV-IRR (2)'!I9 -> 2866085548 | M35: =+'2.NPV-IRR (2)'!J9 -> 0.17009191 | N35: =+'2.NPV-IRR (2)'!K9 -> -1.5831695e+09 | O35: =+'2.NPV-IRR (2)'!L9 -> Loyiha rad etilsin
K36: =+'2.NPV-IRR (2)'!H10 -> 0 | L36: =+'2.NPV-IRR (2)'!I10 -> 3051126205 | M36: =+'2.NPV-IRR (2)'!J10 -> 0.17009191 | N36: =+'2.NPV-IRR (2)'!K10 -> -3.9428327e+08 | O36: =+'2.NPV-IRR (2)'!L10 -> Loyiha rad etilsin
J38: Залог
K39: обеспечение | L39: Оценочная стоимость (Независимая оценка), сум | M39: Оценка сотрудников ГО (КАД) | N39: Залоговая стоимость (акт оценки), сум | O39: Удельный вес
J40: ='3.Кредит таъминоти'!A6 -> 1 | K40: =+'3.Кредит таъминоти'!C6 -> “NARPAY GREEN HOUS 75” MCHJга тегишли Нарпай тумани, Оқ Олтин МФЙда жойлашган нотурар бино иншоати | L40: ='3.Кредит таъминоти'!E6 -> 10029645000 | M40: ='3.Кредит таъминоти'!I6 -> 4795151000 | N40: ='3.Кредит таъминоти'!F6 -> 4790000000 | O40: =Xulosa!N40/'3.Кредит таъминоти'!$F$9 -> 1
J41: 2 | K41: =+'3.Кредит таъминоти'!C8 -> Қўшимча таъминот сифатида “NARPAY GREEN HOUSE 75” МCHJ ва фуқаро Улуғов Шухрат Ҳамдамовичларнинг 6.1 млрд. сўмдан кафилликлари | L41: ='3.Кредит таъминоти'!E8 -> 0 | M41: =L4*125% -> 6125000000
K42: Жами: | N42: =SUM(N40:N41) -> 4790000000 | O42: 1
J44: Кредитная нагрузка
K46: Кредитная нагрузка относительно оборотов
K47: Среднемесячный оборот по счёту | L47: Кредитная нагрузка относительно оборотов | M47: %
...

Sheet 1.Moliyaviy natijalar
A1: 2025 йил якуни бўйича ҳисоботларига асосан | E1: Korxonaning moliyaviy holatini korxona faoliyati uchun muhim bo‘lgan 5 ta koeffitsiyentlar asosida baholash
A2: =Xulosa!K1 -> OOO NARPAY INVIST | E2: Наименавание коэфиициента | F2: Способ расчета | G2: Вес коэффициента | H2: Результат коэффициента | I2: Финальный результат
A3: Наименавание | B3: Строка | C3: Остаток на отчетную дату | E3: Debt Service Coverage Ratio – Қарзга хизмат кўрсатиш коэффициенти Корхонанинг Операцион фойдаси | F3: Ф2: 240 / (Ф1: 570 + Ф1: 730 + Ф2: 180) | G3: 0.05 | H3: =C15/(C10+C11+C14) -> 181354 | I3: =H3*G3 -> 9067.7 | K3: Балл | L3: Тавсифи | M3: Синф
A4: Сумма амортизации (0200) | B4: Ф1 011 | E4: Debt/EBITDA – Умумий қарзнининг корхона EBITDA даромади | F4: Ф2: 240 / (Ф1: 770 + Ф1: 011) | G4: 0.3 | H4: =+C15/(C12+C4) -> 0.089779208 | I4: =H4*G4 -> 0.026933762 | K4: 5 | L4: Mutlaq to‘lovga layoqatli | M4: 20 ballga teng va yuqori
A5: Итого по разделу II тек актив (стр. 140+190+200+210+320+370+380) | B5: Ф1 390 | C5: 1934714.4 | E5: Liquidity ratio – Жорий ликвидлик коэффициенти. | F5: Ф1: 390 / Ф1: 600 | G5: 0.3 | H5: =+C5/C10 -> 1934714.4 | I5: =H5*G5 -> 580414.31 | K5: 4 | L5: Me’yor darajasida toʻlovga layoqatli | M5: 15 ballga teng va yuqori
A6: Всего по активу баланса (стр.130+стр.390) | B6: Ф1 400 | C6: 7087878 | E6: Leverage – Молиявий мустақиллик коэффициенти. | F6: Ф1 480 / Ф1: 400 | G6: 0.3 | H6: =$C$8/$C$6 -> 0.71500638 | I6: =H6*G6 -> 0.21450191 | K6: 3 | L6: Past darajada toʻlovga layoqatli | M6: 10 ballga teng va yuqori
A7: Нераспределенная прибыль (непокрытый убыток) (8700) | B7: Ф1 450 | C7: 14714.38 | E7: Sufficiency of WC – Соф айланма активлар билан таъминганлик коэффициенти | F7: Ф1 390 /Ф1: 400 | G7: 0.05 | H7: =$C$5/$C$6 -> 0.27296102 | I7: =H7*G7 -> 0.013648051 | K7: 2 | L7: Moliyaviy barqaror boʻlmagan | M7: 5 ballga teng va yuqori
A8: итого капитал | B8: Ф1 480 | C8: 5067878 | I8: =SUM(I3:I7) -> 589482.27 | K8: 1 | L8: Risk yuqori | M8: 5 balldan past
A9: Долгосрочные банковские кредиты (7810) | B9: Ф1 570
A10: Текущие обязательства,всего (стр.610+630+640+650+660+670 +680+690+700+710+720+730+740+750+760) | B10: Ф1 600 | C10: 1 | E10: Edward Altman modeli asosida korxonaning bankrotlikka uchrash ehtimolligini aniqlash
A11: Краткосрочные банковские кредиты (6810) | B11: Ф1 730 | E11: E.Altman modeli (Z) =0,717x_1+ 0,847x_2+3,107x_3+0,420x_4+0,998x_5
A12: итого Обя | B12: Ф1 770 | C12: 2020000 | E12: x_1 = Оборот капитали / Жами активлар | F12: Ф1 390 / Ф1 400 | G12: =+C5/C6 -> 0.27296102
A13: Чистая выручка от реализации продукции (товаров, работ и услуг) | B13: Ф2 010 | C13: 108100 | E13: x_2 = Тақсимланмаган фойда / Жами активлар | F13: Ф1 450 / Ф1 400 | G13: =+C7/C6 -> 0.0020759923
A14: Расходы в виде процентов | B14: Ф2 180 | E14: x_3 = Операцион фойда (Солиқ ва фоиз тўлагунга қадар фойда) / Жами активлар | F14: Ф2 240 / Ф1 400 | G14: =+C15/C6 -> 0.025586501 | K14: Балл | L14: Тавсифи | M14: Синф
A15: Прибыль (убыток) до уплаты налога на прибыль (стр.220+/-230) | B15: Ф2 240 | C15: 181354 | E15: x_4 = Ўз маблағларини баланс қиймати / Жами мажбуриятлар | F15: Ф1 480 / Ф1 770 | G15: =+C8/C12 -> 2.5088505 | K15: 5 | L15: Bankrotlikka uchrash ehtimolligi past va moliyaviy barqaror korxona. | M15: Z > 2.9
E16: x_5 = Соф тушум / Жами активлар | F16: Ф2 010 / Ф1 400 | G16: =+C13/C6 -> 0.015251391 | K16: 3 | L16: Bankrotlik holati noaniq boʻlgan korxona, (bashorat qilib boʻlmaydi). | M16: 1.23 < Z < 2.89
A17: Умумий балл: | B17: =K16+K4 -> 8 | G17: =0.717*G12+0.847*G13+3.107*G14+0.42*G15+0.998*G16 -> 1.3459068 | K17: 1 | L17: Bankrotlikka uchrashi ehtimolligi yuqori boʻlgan korxona. | M17: Z < 1.23

Sheet 2.NPV-IRR
A1: LOYIHANING TEXNIK IQTISODIY ASOSLARI KO‘RSATKICHLARI.
A2: 1 | B2: Loyiha valyutasi | E2: =Xulosa!L2 -> UZS | G2: NPV va IRR hisoblanishi
A3: 2 | B3: Loyiha summasi | E3: =Xulosa!L3 -> 9200000000 | G3: Davr | H3: Loyiha bo‘yicha tushumlar sanasi | I3: Sof pul oqimi | J3: Diskont stavka | K3: NPV | L3: IRR
A4: 3 | B4: Kredit summasi | E4: =Xulosa!L4 -> 4900000000 | G4: 0 | I4: =-E3 -> -9200000000
A5: 4 | B5: Korxonaning loyihadagi o‘z ulushi summasi | E5: =E3-E4 -> 4300000000 | G5: 1 | H5: 45717 | I5: 18962852900 | J5: =+$E$10 -> 0.17972826 | K5: 21659886957 | L5: =IF(IRR($I$4:I5,J5)<$E$10,"Loyiha rad etilsin","Loyihani qabul qilish mumkin") -> Loyihani qabul qilish mumkin
A6: 5 | B6: Kredit summasining loyihadagi ulushi (%) | E6: =E4/E3 -> 0.5326087 | G6: 2 | H6: 46082 | I6: 15259242900 | J6: =+$E$10 -> 0.17972826 | K6: 18387662770 | L6: =IF(IRR($I$4:I6,J6)<$E$10,"Loyiha rad etilsin","Loyihani qabul qilish mumkin") -> Loyihani qabul qilish mumkin | M6: Formula shu yerdan pastga qarab tortiladi. Ushbu satr o'chirilmasin.
A7: 6 | B7: Korxonaning loyihadagi o‘z ulushi foizi (%) | E7: =E5/E3 -> 0.4673913 | G7: 3 | H7: 46447 | I7: 42758060400 | J7: =+$E$10 -> 0.17972826 | K7: 19513295472 | L7: =IF(IRR($I$4:I7,J7)<$E$10,"Loyiha rad etilsin","Loyihani qabul qilish mumkin") -> Loyihani qabul qilish mumkin
A8: 7 | B8: Kredit foizi | E8: =+Xulosa!L8 -> 0.14 | G8: 4 | H8: 46813 | I8: 37564011200 | J8: =+$E$10 -> 0.17972826 | K8: 21268438292 | L8: =IF(IRR($I$4:I8,J8)<$E$10,"Loyiha rad etilsin","Loyihani qabul qilish mumkin") -> Loyihani qabul qilish mumkin
A9: 8 | B9: Chet el valyutasidagi bank kreditlari bo‘yicha foiz stavkasi (Markaziy bankning statistik byulleteni) | E9: 0.225 | G9: 5 | H9: 47178 | I9: 62058342400 | J9: =+$E$10 -> 0.17972826 | K9: 23202533279 | L9: =IF(IRR($I$4:I9,J9)<$E$10,"Loyiha rad etilsin","Loyihani qabul qilish mumkin") -> Loyihani qabul qilish mumkin
A10: 9 | B10: WACC (Ставка Дисконта) | E10: =+(E6*E8)+(E7*E9) -> 0.17972826
M11: IRR
A12: Ball | B12: Tavsifi | C12: Sinflar | D12: Kredit muddati (oy/yil) | E12: =Xulosa!L6 -> 84 | M12: =IRR($I$4:I12,J12) -> 2.2136093
A13: 10 | B13: Loyiha 4 oy muddatda o‘zini oqlaydi. | C13: 0,00-0,22 | D13: NPV nechanchi oy/yilda musbat bo'ladi | E13: =G6 -> 2 | M13: =IRR($I$4:I13,J13) -> 2.2136093
A14: 8 | B14: Loyiha 8 oy muddatda o‘zini oqlaydi. | C14: 0,23-0,44 | M14: =IRR($I$4:I14,J14) -> 2.2136093
A15: 6 | B15: Loyiha 12 oy muddatda o‘zini oqlaydi. | C15: 0,45-0,67
A16: 4 | B16: Loyiha 16 oy muddatda o‘zini oqlaydi. | C16: 0,68-0,89
A17: 2 | B17: Loyiha kredit muddatida bajariladi | C17: 0,89-1,00
A18: 0 | B18: Loyiha kredit muddatida bajarilmaydi | C18: 1,00 < | D18: Ball uchun qiymat | E18: =+E13/E12 -> 0.023809524

Sheet 2.NPV-IRR (2)
A1: LOYIHANING TEXNIK IQTISODIY ASOSLARI KO‘RSATKICHLARI.
A2: 1 | B2: Loyiha valyutasi | E2: =[6]Xulosa!L2 -> UZS | G2: NPV va IRR hisoblanishi
A3: 2 | B3: Loyiha summasi | E3: =E4+E5 -> 9200000000 | G3: Davr | H3: Loyiha bo‘yicha tushumlar sanasi | I3: Sof pul oqimi (kredit to‘lovlaridan keyin) | J3: Diskont stavka | K3: NPV | L3: IRR
A4: 3 | B4: Kredit summasi | E4: =Xulosa!L4 -> 4900000000 | G4: 0 | I4: =-E3 -> -9200000000
A5: 4 | B5: Korxonaning loyihadagi o‘z ulushi summasi | E5: =Xulosa!L5 -> 4300000000 | G5: 1 | I5: 2377093102 | J5: =$E$10 -> 0.17009191 | K5: =+NPV($J5,I5)+$I$4 -> -7.1684561e+09 | L5: =IF(IRR($I$4:I5,J5)<$E$10,"Loyiha rad etilsin","Loyihani qabul qilish mumkin") -> Loyiha rad etilsin
A6: 5 | B6: Kredit summasining loyihadagi ulushi (%) | E6: =E4/E3 -> 0.5326087 | G6: 2 | I6: 1805615699 | J6: =$E$10 -> 0.17009191 | K6: =+NPV($J6,$I$5:I6)+$I$4 -> -5.8496366e+09 | L6: =IF(IRR($I$4:I6,J6)<$E$10,"Loyiha rad etilsin","Loyihani qabul qilish mumkin") -> Loyiha rad etilsin | M6: Formula shu yerdan pastga qarab tortiladi. Ushbu satr o'chirilmasin.
A7: 6 | B7: Korxonaning loyihadagi o‘z ulushi foizi (%) | E7: =E5/E3 -> 0.4673913 | G7: 3 | I7: 2451935561 | J7: =$E$10 -> 0.17009191 | K7: =+NPV($J7,$I$5:I7)+$I$4 -> -4.3190809e+09 | L7: =IF(IRR($I$4:I7,J7)<$E$10,"Loyiha rad etilsin","Loyihani qabul qilish mumkin") -> Loyiha rad etilsin
A8: 7 | B8: Kredit foizi | E8: =Xulosa!L8 -> 0.14 | G8: 4 | I8: 2678947117 | J8: =$E$10 -> 0.17009191 | K8: =+NPV($J8,$I$5:I8)+$I$4 -> -2.8899098e+09 | L8: =IF(IRR($I$4:I8,J8)<$E$10,"Loyiha rad etilsin","Loyihani qabul qilish mumkin") -> Loyiha rad etilsin
A9: 8 | B9: Milliy valyutadagi bank kreditlari bo‘yicha foiz stavkasi (Markaziy bankning statistik byulleteni) | E9: 0.23225306 | G9: 5 | I9: 2866085548 | J9: =$E$10 -> 0.17009191 | K9: =+NPV($J9,$I$5:I9)+$I$4 -> -1.5831695e+09 | L9: =IF(IRR($I$4:I9,J9)<$E$10,"Loyiha rad etilsin","Loyihani qabul qilish mumkin") -> Loyiha rad etilsin
A10: 9 | B10: WACC (Ставка Дисконта) | E10: =+(E6*E8)+(E7*E9)*(1-0.12) -> 0.17009191 | G10: 6 | I10: 3051126205 | J10: =$E$10 -> 0.17009191 | K10: =+NPV($J10,$I$5:I10)+$I$4 -> -3.9428327e+08 | L10: =IF(IRR($I$4:I10,J10)<$E$10,"Loyiha rad etilsin","Loyihani qabul qilish mumkin") -> Loyiha rad etilsin
G11: 7 | I11: 3285849340 | J11: =$E$10 -> 0.17009191 | K11: =+NPV($J11,$I$5:I11)+$I$4 -> 6.9994469e+08 | L11: =IF(IRR($I$4:I11,J11)<$E$10,"Loyiha rad etilsin","Loyihani qabul qilish mumkin") -> Loyihani qabul qilish mumkin | M11: IRR
A12: Ball | B12: Tavsifi | C12: Sinflar | D12: Kredit muddati (oy/yil) | E12: 5 | M12: =IRR($I$4:I12,J12) -> 0.19399156
A13: 10 | B13: Loyiha 4 oy muddatda o‘zini oqlaydi. | C13: 0,00-0,22 | D13: NPV nechanchi oy/yilda musbat bo'ladi | E13: 5 | M13: =IRR($I$4:I13,J13) -> 0.19399156
A14: 8 | B14: Loyiha 8 oy muddatda o‘zini oqlaydi. | C14: 0,23-0,44 | M14: =IRR($I$4:I14,J14) -> 0.19399156
A15: 6 | B15: Loyiha 12 oy muddatda o‘zini oqlaydi. | C15: 0,45-0,67
A16: 4 | B16: Loyiha 16 oy muddatda o‘zini oqlaydi. | C16: 0,68-0,89
A17: 10 | B17: Loyiha kredit muddatida bajariladi | C17: 0,89-1,00
A18: 0 | B18: Loyiha kredit muddatida bajarilmaydi | C18: 1,00 < | D18: Ball uchun qiymat | E18: =+E13/E12 -> 1

Sheet 3.Кредит таъминоти
B1: СТРУКТУРИРОВАНИЕ ОБЕСПЕЧЕНИЯ ПО КРЕДИТУ
A3: Планируемое обеспечение по кредиту
A4: Информации по имущественным залогам
A5: № | B5: Тип залога | C5: Описание залога | D5: Условия залога Не последующий залог | E5: Оценочная стоимость (Независимая оценка), сум | F5: Залоговая стоимость (акт оценки), сум | G5: Свободная часть последующего залог | H5: Дисконт оценки, % | I5: Оценка сотрудников ГО (КАД) | J5: Общая земельная площадь, кв.м. - недвижимость | K5: Стоимость по E-Baholash | L5: Кадастровый номер / Номер кузова автомобиля/Стоимость по ГТД, в валюте - если оборудование | M5: ИНН залогодателя | N5: Адрес объекта залога/ поручителя
A6: 1 | B6: Кўчмас мулк | C6: “NARPAY GREEN HOUS 75” MCHJга тегишли Нарпай тумани, Оқ Олтин МФЙда жойлашган нотурар бино иншоати | D6: до выдачи кредита | E6: 10029645000 | F6: 4790000000 | I6: 4795151000
B7: Ускуналар-Суғурта полиси | C7: Кредит ҳисобига сотиб олиниши режалаштирилаётган мевани қайта ишлаб чиқариш ускуналари, етиб келгунига қадар кредит қайтмаслик хатари бўйича суғурта полиси | D7: - | F7: 1335000000
A8: 2 | B8: Кафиллик | C8: Қўшимча таъминот сифатида “NARPAY GREEN HOUSE 75” МCHJ ва фуқаро Улуғов Шухрат Ҳамдамовичларнинг 6.1 млрд. сўмдан кафилликлари | D8: - | F8: 6125000000
A9: ВСЕГО до выдача кредита | E9: до выдачи кредита | F9: =+SUMIF(D6:D8,E9,F6:F8)+F46 -> 4790000000 | G9: =+F9/Xulosa!L4 -> 0.97755102
A10: ВСЕГО после выдача кредита | E10: после выдачи кредита | F10: =+SUMIF(D6:D8,E10,F6:F8) -> 0 | G10: =+F10/Xulosa!L4 -> 0
A11: ИТОГО | F11: =+F10+F9 -> 4790000000 | G11: =+F11/Xulosa!L4 -> 0.97755102
A14: № | B14: Quyidagilar ta'minot sifatida qabul qilinishi mumkin: | C14: Likvidlilik darajasi | D14: Vazni | E14: Ta'minot ulushi | F14: Ball
A15: 1 | B15: O'zbekiston Respublikasi Hukumatining (bundan buyon matnda Hukumat deb yuritiladi) kafolati; | C15: Eng yuqori likvidli garov | D15: 10 | F15: =D15*E15 -> 0
A16: 2 | B16: Tijorat banklarida ochilgan hisobvaraqlardagi milliy va xorijiy valyutada shakllantirilgan depozitlar, shuningdek, depozit sertifikatlari shaklidagi garov; | D16: 10 | F16: =D16*E16 -> 0
A17: 3 | B17: Davlat qimmatli qog'ozlari garovi; | D17: 10 | F17: =D17*E17 -> 0
A18: 4 | B18: Markaziy bankning qimmatli qog'ozlari shaklidagi gаrоч; | D18: 10 | F18: =D18*E18 -> 0
A19: 5 | B19: Jahon banki guruhi (Хаlqаrо tiklanish va taraqqiyot banki, Xalqaro moliya korporatsiyasi, Xalqaro investitsiyalarni kafolatlash agentligi, Xalqaro taraqqiyot assotsiatsiyasi) hamda Osiyo taraqqiyot banki, Osiyo infrastruktura investitsiya banki, Yevropa tiklanish va taraqqiyot banki, Yevropa investitsiya banki, Yevropa investitsiya jamg'armasi, Islom taraqqiyot banki va Yevropa Kengashining taraqqiyot banklari kafolati; | D19: 10 | F19: =D19*E19 -> 0
A20: 6 | B20: Qimmatbaho metallar shaklidagi oltin va kumush quymalari shaklidagi zaka|at; | D20: 10 | F20: =D20*E20 -> 0
A21: 7 | B21: Ko'chmas mulk, jumladan, pudrat tashkilotlariga ajratiladigan kreditlar bo'yicha davlat ro'yxatidan o'tkazilgan, ko'p qavatli uy-joylarning qurilishi yakunlangan qismi (qavatlari) garovi (bosqichma-bosqich garovga olinishi mumkin); | C21: O'rta darajadagi likvidli garov | D21: 8 | E21: =F6/Xulosa!L4 -> 0.97755102 | F21: =D21*E21 -> 7.8204082
A22: 8 | B22: Qurilishi tugallanmagan binolar | D22: 7
A23: 9 | B23: Asbob-uskuna | C23: Past darajadagi likvidli garov | D23: 6 | F23: =D23*E23 -> 0
A24: 10 | B24: Maxsus texnika | D24: 6 | F24: =D24*E24 -> 0
A25: 11 | B25: Xo'jalik jamiyatidagi ulushga bo'lgan huquq; | D25: 4 | F25: =E25*D25 -> 0
A26: 12 | B26: Boshqa qimmatli qog'ozlar shaklidagi garov; | C26: Quyi darajadagi likvidli garov | D26: 5 | F26: =D26*E26 -> 0
A27: 13 | B27: Yuridik va jismoniy shaxslarning kafilliklari; | D27: 2 | F27: =D27*E27 -> 0
A28: 14 | B28: Boshqa tijorat banklari va sug'urta tashkilotlari kafolatlari; | D28: 2 | F28: =D28*E28 -> 0
A29: 15 | B29: O'z faoliyatini qonunchilikda belgilangan tartibda аmаlgа oshiruvchi, tegishli litsenziyaga еgа sug'urta kompaniyalarining kreditni qaytaгilmaslik xatarining sug'urtalanganligi to'g'risidagi sug'urta polislari ча O'zbekiston Respublikasi qonunchiligida ko'zda tutilgan boshqa ta'minot turlari. | D29: 2 | F29: =D29*E29 -> 0
F30: =SUM(F15:F29) -> 7.8204082
B32: Ball | C32: Tavsifi | D32: Sinf
B33: 10 | C33: Eng yuqori likvidli garov | D33: 10
B34: 8 | C34: O'rta darajadagi likvidli garov | D34: 8-9,9
B35: 6 | C35: Past darajadagi likvidli garov | D35: 6-7,9
B36: 4 | C36: Past darajadagi likvidli garov | D36: 4-5,9
B37: 2 | C37: Quyi darajadagi likvidli garov | D37: 2,1-3,9
B38: 0 | C38: Quyi darajadagi likvidli garov | D38: 0-2
A42: Информации о неимущественном обеспечений
A44: № | B44: Тип поручительство | C44: Наименования поручителя | D44: Категория поручительство | E44: Валюта поручительство | F44: Сумма поручительства | G44: Чистые активы (строка 480 баланса поручителя) | H44: Максимально допустимая сумма поручительства | I44: ИНН залогодателя
A45: 1
A48: ВСЕГО | F48: =+F45+F46+F47 -> 0 | G48: =SUM(G45:G45) -> 0 | H48: =SUM(H45:H46) -> 0
A50: ВСЕГО (имущественный залог + неимущественный залог)

Sheet 4. Кредит тарихи
A1: Информация о действующих обязательствах (данные берутся с АСОКИ и КАТМ)
A3: № | B3: Банк кредитор | C3: Филиал | D3: Тип продукта | E3: Вид кредита | F3: Валюта кредита (UZS, USD, EUR) | G3: Сумма договора (в номинале) | H3: Дата начала | I3: Дата погашения | J3: Остаток срочного основного долга (номинал) | K3: Остаток просроченного основного долга (номинал) | L3: Остаток просроченных % (номинал) | M3: Остаток % на счёте 91501 (номинал) | N3: % ставка по кредиту | O3: Ежемесячный платеж по кредиту | P3: ИТОГО долг клиента (номинал и эквивалент) | Q3: Кол-во случаев переходящего просроченного основного долга на следующий месяц по кредитам MKB за последние 12 месяцев
B4: 1 | C4: 2 | D4: 3 | E4: 4 | F4: 5 | G4: 6 | H4: 7 | I4: 8 | J4: 9 | K4: 10 | L4: 11 | M4: 12 | N4: 13 | O4: 14 | P4: 15=9+10+14 | Q4: 16 | S4: Курс доллара США | U4: сум
A5: 1 | S5: Курс ЕВРО | U5: сум
A6: 2 | S6: Курс РУБЛ | U6: сум
A7: 3 | S7: Базовая расчетная величина | U7: сум
A8: 5
A9: 6
A10: 7
B11: ИТОГО UZS | C11: - | E11: - | F11: UZS | G11: =+G5+G6 -> 0 | H11: - | I11: - | J11: =+SUM(J10:J10) -> 0 | K11: =SUM(K7:K10) -> 0 | L11: =SUMIF($O$66:$O$66,$O$69,L6:L6) -> 0 | M11: =SUMIF($O$66:$O$66,$O$69,M5:M5) -> 0 | N11: - | O11: =+SUM(O10:O10) -> 0 | P11: =P5+P6+P7+#REF! -> #REF! | Q11: -
B12: ИТОГО USD | C12: - | E12: - | F12: USD | G12: =+G7 -> 0 | H12: - | I12: - | J12: =+J7 -> 0 | K12: =SUMIF($O$66:$O$66,$O$70,K5:K5) -> 0 | L12: =SUMIF($O$66:$O$66,$O$70,L6:L6) -> 0 | M12: =SUMIF($O$66:$O$66,$O$70,M5:M5) -> 0 | N12: - | O12: =+O5+O6 -> 0 | P12: =#REF! -> #REF! | Q12: -
B13: ИТОГО EUR | C13: - | E13: - | F13: EUR | G13: 0 | H13: - | I13: - | J13: 0 | K13: =SUMIF($O$66:$O$66,$O$71,K5:K5) -> 0 | L13: =SUMIF($O$66:$O$66,$O$71,L6:L6) -> 0 | M13: =SUMIF($O$66:$O$66,$O$71,M5:M5) -> 0 | O13: =+SUM(O7:O9) -> 0 | P13: =SUMIF($O$66:$O$66,$O$71,P5:P5) -> 0 | Q13: -
B14: Jami | C14: - | E14: - | G14: =+SUM(G5:G10) -> 0 | H14: - | I14: - | J14: =+SUM(J5:J10) -> 0 | K14: =K11+(K12*$M$13)+(K13*$M$14) -> 0 | L14: =L11+(L12*$M$13)+(L13*$M$14) -> 0 | M14: =M11+(M12*$M$13)+(M13*$M$14) -> 0 | N14: - | O14: =+SUM(O5:O10) -> 0 | P14: =P11+(P12*$M$13)+(P13*$M$14) -> 0 | Q14: =SUM(Q5:Q5) -> 0
L15: Ежемесячная нагрузка по оплате
L16: Yangi kredit uchun maksimal oylik to‘lov | O16: 1.3992968e+08
L17: Jami oylik to'lov | O17: =O15+O16 -> 1.3992968e+08
A18: Ball | B18: Tavsifi
A19: 10 | B19: Кредит қарздорлиги йуқ, корхона томонидан олиндан кредит қарзларни ўз вақтида ва муддатидан аввал тўланган.
A20: 8 | B20: Кредит маблағлари олинган, бугунги кунда муддати ўтган қарздорлиги йуқ.
A21: 6 | B21: Корхона томонидан кредит маблағлари олинмаган. (Тўлаш қобилияти аниқ бўлмаганлиги учун)
A22: 4 | B22: Кредит маблағлари олинган, бугунги кунда муддати ўтган қарздорлиги бор.
A23: 0 | B23: Кредит маблағлари олинган, муддати ўтган қарздорлиги бор, кўп марта графикни бўзиб тўлаган, судга оширилган.

Sheet 5. ҲР айланма ва қарз юки
A1: Информация об оборотах компани по расчётным счетам (наличие других счетов сверить с НИББД)
A3: Обслуживающий банк | B3: Расчетный счет | C3: Период (начало-конец) | E3: Валюта счёта | F3: Дебет | G3: Кредит | H3: Среднемесячный оборот по счёту | J3: Курс доллара США | K3: =+Xulosa!P2 -> 0 | L3: сум
A4: Агробанк | B4: 20208000405612490001 | C4: 45658 | D4: 46022 | E4: UZS | F4: 166591000 | G4: 1.7058764e+08 | H4: =IFERROR(G4/((D4-C4)/30),0) -> 14059421 | J4: Курс ЕВРО | L4: сум
A5: МКБ | B5: 20208000405612490001 | C5: 45678 | D5: 46042 | E5: UZS | F5: 5.1364124e+08 | G5: 533752000 | H5: =IFERROR(G5/((D5-C5)/30),0) -> 43990549 | J5: Курс РУБЛ | L5: сум
J6: Базовая расчетная величина | L6: сум
A9: ИТОГО UZS | E9: UZS | F9: =SUMIF(E4:E8,E9,F4:F8) -> 6.8023224e+08 | G9: =SUMIF(E4:E8,E9,G4:G8) -> 7.0433964e+08 | H9: =SUM(H4:H8) -> 58049970
A10: ИТОГО USD | E10: USD | F10: =SUMIF(E4:E8,E10,F4:F8) -> 0 | G10: =SUMIF(E4:E8,E10,G4:G8) -> 0 | H10: =SUMIF(E4:E8,E10,H4:H8) -> 0
A11: ИТОГО EUR | E11: EUR | F11: =SUMIF(E4:E8,E11,F4:F8) -> 0 | G11: =SUMIF(E4:E8,E11,G4:G8) -> 0 | H11: =SUMIF(E4:E8,E11,H4:H8) -> 0
A12: ИТОГО РУБЛЬ | E12: РУБЛЬ | F12: =SUMIF(E4:E8,E12,F4:F8) -> 0 | G12: =SUMIF(E4:E8,E12,G4:G8) -> 0 | H12: =SUMIF(E4:E8,E12,H4:H8) -> 0
A13: ИТОГО UZS | E13: UZS | F13: =F9+(F10*K3)+(F11*K4)+(F12*K5) -> 6.8023224e+08 | G13: =G9+(G10*K3)+(G11*K4)+(G12*K5) -> 7.0433964e+08 | H13: =H9+(H10*K3)+(H11*K4)+(H12*K5) -> 58049970
C16: Кредитная нагрузка относительно оборотов
C17: Соха | D17: O’rtacha 1 oylik debet aylnama | E17: O’rtacha 1 oylik qarz yuki | F17: Nisbati
D19: =+H13 -> 58049970 | E19: =+'4. Кредит тарихи'!O17 -> 1.3992968e+08 | F19: =E19/D19 -> 2.4105039
B22: Ball | C22: Tavsifi | D22: Sinf
B23: 10 | C23: Yaxshi | D23: (0-20% гача)
B24: 8 | C24: Qoniqarli | D24: 20%-30% гача)
B25: 5 | C25: Qoniqarsiz | D25: (30%-50% гача)
B26: 3 | C26: O‘ta qoniqarsiz | D26: (50-100% ва ундан юқори) | E26: =F19 -> 2.4105039

Sheet 6.Likvidlik ko‘rsatkich o‘zgari
A1: Kredit berishning moliyaviy ko'rsatkichlarga ta'siri | L1: UZS | M1: USD | N1: EUR
A2: Summa | B2: =Xulosa!L4 -> 4900000000 | C2: UZS | D2: Muddat | E2: =Xulosa!L6 -> 84 | F2: льготн. п. | G2: 24 | H2: USDUZS | I2: =+Xulosa!P2 -> 0 | J2: =+IF(C2="UZS",B2,I2*B2)/1000 -> 4900000 | K2: =Xulosa!L8 -> 0.14
A3: № | B3: Ko'rsatkichlar | C3: Hozirgi holat 01.01.2026 | F3: Kredit ajratilgandan keyingi holat | I3: O'zgarishi
C4: Jami | D4: Milliy valyuta | E4: Xorijiy valyuta | F4: Jami | G4: Milliy valyuta | H4: Xorijiy valyuta | I4: Jami | J4: Milliy valyuta | K4: Xorijiy valyuta
A5: 1 | B5: Yuqori likvidli aktivlarning jami aktivlardagi ulushi (YuLA, min 10%) | C5: =+H32 -> 0.30763614 | D5: =+I32 -> 0.20981303 | E5: =+J32 -> 0.47704989 | F5: =+K32 -> 0.30751383 | G5: =+L32 -> 0.20968149 | H5: =+M32 -> 0.47704989 | I5: =+F5-C5 -> -0.00012230161 | J5: =+G5-D5 -> -0.00013154529 | K5: =+H5-E5 -> 0
A6: 2 | B6: Likvidlilikni qoplash me’yori (LCR, min 100%) | C6: =+H36 -> 2.3192898 | D6: =+I36 -> 1.175669 | E6: =+J36 -> 8.9521132 | F6: =+K36 -> 2.3190001 | G6: =+L36 -> 1.1754968 | H6: =+M36 -> 8.9521132 | I6: =+F6-C6 -> -0.00028971749 | J6: =+G6-D6 -> -0.00017217815 | K6: =+H6-E6 -> 0
A7: 3 | B7: Sof barqaror moliyashtirish me'yori (min 100%) | C7: =+H42 -> 1.1265345 | D7: =+I42 -> 1.0896293 | E7: =+J42 -> 1.2854454 | F7: =+K42 -> 1.1302846 | G7: =+L42 -> 1.0960575 | H7: =+M42 -> 1.2784471 | I7: =+F7-C7 -> 0.0037501717 | J7: =+G7-D7 -> 0.0064282346 | K7: =+H7-E7 -> -0.0069983494
A8: 4 | B8: RWA (min 13%) | C8: =+H63 -> 0.18294485 | F8: =+I63 -> 0.18290081 | I8: =+F8-C8 -> -4.4034852e-05
B10: 15000000000
B11: 1 | E11: 45093
B12: =+B11*B10/1000 -> 15000000 | C12: 45448 | D12: =+$B$12/12 -> 1250000 | E12: =+C12-$E$11 -> 355 | F12: =+IF(E12<1,"Муддатсиз",IF(E12<8,"1-7 кун",IF(E12<31,"8-30 кун",IF(E12<91,"31-90 кун",IF(E12<181,"91-180 кун",IF(E12<366,"181-365 кун",IF(E12<731,"366-730 кун",IF(E12>=731,"2 йилдан кўп")))))))) -> 181-365 кун | G12: 181-365 кун | H12: =+SUMIF($F$12:$F$26,G12,$D$12:$D$26) -> 1250000
C13: 45478 | D13: =+$B$12/12 -> 1250000 | E13: =+C13-$E$11 -> 385 | F13: =+IF(E13<1,"Муддатсиз",IF(E13<8,"1-7 кун",IF(E13<31,"8-30 кун",IF(E13<91,"31-90 кун",IF(E13<181,"91-180 кун",IF(E13<366,"181-365 кун",IF(E13<731,"366-730 кун",IF(E13>=731,"2 йилдан кўп")))))))) -> 366-730 кун | G13: 366-730 кун | H13: =+SUMIF($F$12:$F$26,G13,$D$12:$D$26) -> 13750000
B14: 17991427927 | C14: 45509 | D14: =+$B$12/12 -> 1250000 | E14: =+C14-$E$11 -> 416 | F14: =+IF(E14<1,"Муддатсиз",IF(E14<8,"1-7 кун",IF(E14<31,"8-30 кун",IF(E14<91,"31-90 кун",IF(E14<181,"91-180 кун",IF(E14<366,"181-365 кун",IF(E14<731,"366-730 кун",IF(E14>=731,"2 йилдан кўп")))))))) -> 366-730 кун | G14: 2 йилдан кўп | H14: =+SUMIF($F$12:$F$26,G14,$D$12:$D$26) -> 0
B15: 17991427927 | C15: 45540 | D15: =+$B$12/12 -> 1250000 | E15: =+C15-$E$11 -> 447 | F15: =+IF(E15<1,"Муддатсиз",IF(E15<8,"1-7 кун",IF(E15<31,"8-30 кун",IF(E15<91,"31-90 кун",IF(E15<181,"91-180 кун",IF(E15<366,"181-365 кун",IF(E15<731,"366-730 кун",IF(E15>=731,"2 йилдан кўп")))))))) -> 366-730 кун
B16: =+B14-B15 -> 0 | C16: 45570 | D16: =+$B$12/12 -> 1250000 | E16: =+C16-$E$11 -> 477 | F16: =+IF(E16<1,"Муддатсиз",IF(E16<8,"1-7 кун",IF(E16<31,"8-30 кун",IF(E16<91,"31-90 кун",IF(E16<181,"91-180 кун",IF(E16<366,"181-365 кун",IF(E16<731,"366-730 кун",IF(E16>=731,"2 йилдан кўп")))))))) -> 366-730 кун
C17: 45601 | D17: =+$B$12/12 -> 1250000 | E17: =+C17-$E$11 -> 508 | F17: =+IF(E17<1,"Муддатсиз",IF(E17<8,"1-7 кун",IF(E17<31,"8-30 кун",IF(E17<91,"31-90 кун",IF(E17<181,"91-180 кун",IF(E17<366,"181-365 кун",IF(E17<731,"366-730 кун",IF(E17>=731,"2 йилдан кўп")))))))) -> 366-730 кун
C18: 45631 | D18: =+$B$12/12 -> 1250000 | E18: =+C18-$E$11 -> 538 | F18: =+IF(E18<1,"Муддатсиз",IF(E18<8,"1-7 кун",IF(E18<31,"8-30 кун",IF(E18<91,"31-90 кун",IF(E18<181,"91-180 кун",IF(E18<366,"181-365 кун",IF(E18<731,"366-730 кун",IF(E18>=731,"2 йилдан кўп")))))))) -> 366-730 кун
C19: 45662 | D19: =+$B$12/12 -> 1250000 | E19: =+C19-$E$11 -> 569 | F19: =+IF(E19<1,"Муддатсиз",IF(E19<8,"1-7 кун",IF(E19<31,"8-30 кун",IF(E19<91,"31-90 кун",IF(E19<181,"91-180 кун",IF(E19<366,"181-365 кун",IF(E19<731,"366-730 кун",IF(E19>=731,"2 йилдан кўп")))))))) -> 366-730 кун
C20: 45693 | D20: =+$B$12/12 -> 1250000 | E20: =+C20-$E$11 -> 600 | F20: =+IF(E20<1,"Муддатсиз",IF(E20<8,"1-7 кун",IF(E20<31,"8-30 кун",IF(E20<91,"31-90 кун",IF(E20<181,"91-180 кун",IF(E20<366,"181-365 кун",IF(E20<731,"366-730 кун",IF(E20>=731,"2 йилдан кўп")))))))) -> 366-730 кун
C21: 45721 | D21: =+$B$12/12 -> 1250000 | E21: =+C21-$E$11 -> 628 | F21: =+IF(E21<1,"Муддатсиз",IF(E21<8,"1-7 кун",IF(E21<31,"8-30 кун",IF(E21<91,"31-90 кун",IF(E21<181,"91-180 кун",IF(E21<366,"181-365 кун",IF(E21<731,"366-730 кун",IF(E21>=731,"2 йилдан кўп")))))))) -> 366-730 кун
C22: 45752 | D22: =+$B$12/12 -> 1250000 | E22: =+C22-$E$11 -> 659 | F22: =+IF(E22<1,"Муддатсиз",IF(E22<8,"1-7 кун",IF(E22<31,"8-30 кун",IF(E22<91,"31-90 кун",IF(E22<181,"91-180 кун",IF(E22<366,"181-365 кун",IF(E22<731,"366-730 кун",IF(E22>=731,"2 йилдан кўп")))))))) -> 366-730 кун
C23: 45782 | D23: =+$B$12/12 -> 1250000 | E23: =+C23-$E$11 -> 689 | F23: =+IF(E23<1,"Муддатсиз",IF(E23<8,"1-7 кун",IF(E23<31,"8-30 кун",IF(E23<91,"31-90 кун",IF(E23<181,"91-180 кун",IF(E23<366,"181-365 кун",IF(E23<731,"366-730 кун",IF(E23>=731,"2 йилдан кўп")))))))) -> 366-730 кун
C24: =+C25-J2 -> 0
C25: =+SUM(C27:C146) -> 4900000
B26: =+J2/(E2-G2) -> 81666.667
A27: 1 | B27: 46054
A28: 2 | B28: 46082
A29: 3 | B29: 46113 | H29: Normativ "L" fayl
A30: 4 | B30: 46143 | H30: Joriy holat | K30: Kredit ajratilgandan so`ng | N30: Farqi
A31: 5 | B31: 46174 | E31: Миллий валютада | F31: Хорижий валютада | H31: Жами | I31: Миллий валютада | J31: Хорижий валютада | K31: Жами | L31: Миллий валютада | M31: Хорижий валютада | N31: Жами | O31: Миллий валютада | P31: Хорижий валютада
A32: 6 | B32: 46204 | G32: Юқори ликвидли активларнинг жами активларга нисбати | H32: =+H33/H34 -> 0.30763614 | I32: =+I33/I34 -> 0.20981303 | J32: =+J33/J34 -> 0.47704989 | K32: =+K33/K34 -> 0.30751383 | L32: =+L33/L34 -> 0.20968149 | M32: =+M33/M34 -> 0.47704989 | N32: =+K32-H32 -> -0.00012230161 | O32: =+L32-I32 -> -0.00013154529 | P32: =+M32-J32 -> 0
A33: 7 | B33: 46235 | E33: 0 | F33: 0 | G33: Юқори ликвидли активлар | H33: 3790233108 | I33: 1638752419 | J33: 2151480689 | K33: =+L33+M33 -> 3790233108 | L33: =+I33+$E33 -> 1638752419 | M33: =+J33+$F33 -> 2151480689 | N33: =+O33+P33 -> 0 | O33: =+L33-I33 -> 0 | P33: =+M33-J33 -> 0
A34: 8 | B34: 46266 | E34: =C25 -> 4900000 | F34: =+C193 -> 0 | G34: Жами активлар (РЕПО битимлари айрилган ҳолда) | H34: 12320506818 | I34: 7810536784 | J34: 4509970034 | K34: =+L34+M34 -> 12325406818 | L34: =+I34+$E34 -> 7815436784 | M34: =+J34+$F34 -> 4509970034 | N34: =+O34+P34 -> 4900000 | O34: =+L34-I34 -> 4900000 | P34: =+M34-J34 -> 0
A35: 9 | B35: 46296
A36: 10 | B36: 46327 | G36: Ликвидлиликни қоплаш меъёри коэффициенти | H36: =+H37/H38 -> 2.3192898 | I36: =+I37/I38 -> 1.175669 | J36: =+J37/J38 -> 8.9521132 | K36: =+K37/K38 -> 2.3190001 | L36: =+L37/L38 -> 1.1754968 | M36: =+M37/M38 -> 8.9521132 | N36: =+K36-H36 -> -0.00028971749 | O36: =+L36-I36 -> -0.00017217815 | P36: =+M36-J36 -> 0
A37: 11 | B37: 46357 | E37: 0 | F37: 0 | G37: Юқори ликвидли активлар | H37: 3790233108 | I37: 1638752419 | J37: 2151480689 | K37: =+L37+M37 -> 3790233108 | L37: =+L33 -> 1638752419 | M37: =+M33 -> 2151480689 | N37: =+O37+P37 -> 0 | O37: =+L37-I37 -> 0 | P37: =+M37-J37 -> 0
A38: 12 | B38: 46388 | E38: 0 | F38: 0 | G38: Кейинги 30 кун ичида соф чиқим | H38: 1.6342214e+09 | I38: 1.3938893e+09 | J38: 2.4033216e+08 | K38: =+K39-K40 -> 1.6344256e+09 | L38: =+L39-L40 -> 1.3940934e+09 | M38: =+M39-M40 -> 2.4033216e+08 | N38: =+O38+P38 -> 204166.67 | O38: =+L38-I38 -> 204166.67 | P38: =+M38-J38 -> 0
A39: 13 | B39: 46419 | D39: 0.05 | E39: =C25*D39 -> 245000 | G39: 30 кунлик чиқим суммаси | H39: 2.8484712e+09 | I39: 1.8871426e+09 | J39: 9.6132864e+08 | K39: =+L39+M39 -> 2.8487162e+09 | L39: =+I39+$E39 -> 1.8873876e+09 | M39: =+J39+$F39 -> 9.6132864e+08 | N39: =+O39+P39 -> 245000 | O39: =+L39-I39 -> 245000 | P39: =+M39-J39 -> 0
A40: 14 | B40: 46447 | D40: 0.5 | E40: =B26*D40 -> 40833.333 | G40: 30 кунлик кирим суммаси | H40: 1.2142498e+09 | I40: 4.9325333e+08 | J40: 7.2099648e+08 | K40: =+L40+M40 -> 1.2142906e+09 | L40: =+I40+$E40 -> 4.9329416e+08 | M40: =+J40+$F40 -> 7.2099648e+08 | N40: =+O40+P40 -> 40833.333 | O40: =+L40-I40 -> 40833.333 | P40: =+M40-J40 -> 0
A41: 15 | B41: 46478
...

Sheet 7.Risk appetitga ta'siri
B1: Ajratilayotgan kreditning Bank Risk Appetitiga (Kredit mahsuloti turlarining kredit portfelidagi ulushiga) ta'siri 01.01.2026
B2: Ko`rsatkichlar | C2: Max/min | D2: Limit chegarasi | E2: Signal chegarasi | F2: Past risk | G2: O‘rta risk | H2: Yuqori risk | I2: Segment porfeli | J2: Ajratilayotgan kredit summasi | K2: Bank kredit portfeli | L2: 46023 | M2: Kredit ajratilgach
B3: Korporativ biznes portfeli / Bank kredit porfeli | C3: max | D3: 0.45 | E3: 0.44 | F3: <44% | G3: 44%<….<45% | H3: ≥45% | I3: 7.5142789e+12 | J3: =Xulosa!L4 -> 4900000000 | K3: =+J3+$I$3+$I$4+$I$5+$I$6 -> 2.0282791e+13 | L3: =+I3/I7 -> 0.3705651 | M3: =+(I3+J3)/K3 -> 0.37071716 | N3: Past risk
B4: Kichik biznes portfeli / Bank kredit porfeli | C4: max | D4: 0.25 | E4: 0.22 | F4: <22% | G4: 22%<….<25% | H4: ≥25% | I4: 4.2373221e+12 | K4: =+J4+$I$3+$I$4+$I$5+$I$6 -> 2.0277891e+13 | L4: =+I4/$I$7 -> 0.20896266 | M4: =+(I4+J4)/K4 -> 0.20896266
B5: Chakana biznes portfeli / Bank kredit porfeli | C5: max | D5: 0.25 | E5: 0.22 | F5: <22% | G5: 22%<….<25% | H5: ≥25% | I5: 4.6595017e+12 | K5: =+J5+$I$3+$I$4+$I$5+$I$6 -> 2.0277891e+13 | L5: =+I5/$I$7 -> 0.22978236 | M5: =+(I5+J5)/K5 -> 0.22978236
B6: Ijtimoiy kreditlar portfeli / Bank kredit porfeli | C6: max | D6: 0.29 | E6: 0.26 | F6: <26% | G6: 26%<….<29% | H6: ≥29% | I6: 3.8667887e+12 | K6: =+J6+$I$3+$I$4+$I$5+$I$6 -> 2.0277891e+13 | L6: =+I6/$I$7 -> 0.19068988 | M6: =+(I6+J6)/K6 -> 0.19068988
I7: =SUM(I3:I6) -> 2.0277891e+13

Sheet 8.Yuqori foiz stavkada kredit
B1: Ajratilayotgan kreditning Bank Risk Appetitiga (Yuqori foiz stavkada ajratilgan kreditlarning kredit portfelidagi hamda sohalar bo‘yicha ulushlariga) ta'siri 01.12.2025
B2: Ko`rsatkichlar | C2: Max/min | D2: Limit chegarasi | E2: Signal chegarasi | F2: Past risk | G2: O‘rta risk | H2: Yuqori risk | I2: Riskka tortilgan kreditlar porfeli | J2: Ajratilayotgan kredit summasi | K2: Segment portfeli | L2: 45962 | M2: Kredit ajratilgach
B3: Korporativ biznes portfelidagi yuqori foizli kreditlar / Korporativ biznes portfeli | C3: max | D3: 0.24 | E3: 0.22 | F3: <22% | G3: 22%<….<24% | H3: ≥24% | I3: 1.6148736e+12 | J3: =Xulosa!L4 -> 4900000000 | K3: 7.6113361e+12 | L3: =+I3/K3 -> 0.2121669 | M3: =+(I3+J3)/K3 -> 0.21281067 | N3: Past risk
B4: Kichik biznes portfeli / Bank kredit porfeli | C4: max | D4: 0.3 | E4: 0.28 | F4: <28% | G4: 28%<….<30% | H4: ≥30% | I4: 9.1167253e+11 | K4: 4.1764618e+12 | L4: =+I4/K4 -> 0.21828825 | M4: =+(I4+J4)/K4 -> 0.21828825
B5: Chakana biznes portfeli / Bank kredit porfeli | C5: max | D5: 0.3 | E5: 0.28 | F5: <28% | G5: 28%<….<30% | H5: ≥30% | I5: 1.9522877e+12 | K5: 4.5338131e+12 | L5: =+I5/K5 -> 0.43060612 | M5: =+(I5+J5)/K5 -> 0.43060612
G6: jami kredit portfeli | I6: =+SUM(I3:I5) -> 4.4788338e+12 | K6: 2.0352379e+13 | L6: =+I6/K6 -> 0.22006439 | M6: =+(I6+J6)/K6 -> 0.22006439
